test_anagram (__main__.TestExercice) ... FAIL
test_doubles (__main__.TestExercice) ... ERROR
test_grades (__main__.TestExercice) ... FAIL
test_histogram (__main__.TestExercice) ... FAIL
test_order (__main__.TestExercice) ... ERROR

======================================================================
ERROR: test_doubles (__main__.TestExercice)
----------------------------------------------------------------------
Traceback (most recent call last):
  File "test_exercice.py", line 49, in test_doubles
    output = [exercice.contains_doubles(v) for v in values]
  File "test_exercice.py", line 49, in <listcomp>
    output = [exercice.contains_doubles(v) for v in values]
  File "/home/runner/work/c03_ch6_exercices-krab-z/c03_ch6_exercices-krab-z/exercice.py", line 29, in contains_doubles
    for i in range(0,len(list)):
TypeError: object of type 'type' has no len()

======================================================================
ERROR: test_order (__main__.TestExercice)
----------------------------------------------------------------------
Traceback (most recent call last):
  File "test_exercice.py", line 19, in test_order
    output = [exercice.order(v) for v in values]
  File "test_exercice.py", line 19, in <listcomp>
    output = [exercice.order(v) for v in values]
  File "/home/runner/work/c03_ch6_exercices-krab-z/c03_ch6_exercices-krab-z/exercice.py", line 10, in order
    liste.append(int(input("Entrer les valeurs :")))
EOFError: EOF when reading a line

======================================================================
FAIL: test_anagram (__main__.TestExercice)
----------------------------------------------------------------------
Traceback (most recent call last):
  File "test_exercice.py", line 40, in test_anagram
    'Erreur dans la vérification de l\'anagramme'
AssertionError: Lists differ: [False, False] != [True, False]

First differing element 0:
False
True

- [False, False]
+ [True, False] : Erreur dans la vérification de l'anagramme

======================================================================
FAIL: test_grades (__main__.TestExercice)
----------------------------------------------------------------------
Traceback (most recent call last):
  File "test_exercice.py", line 69, in test_grades
    'Erreur dans les notes'
AssertionError: [{}] is not an instance of <class 'dict'> : First argument is not a dictionary

======================================================================
FAIL: test_histogram (__main__.TestExercice)
----------------------------------------------------------------------
Traceback (most recent call last):
  File "test_exercice.py", line 84, in test_histogram
    'Erreur dans les histogrammes'
AssertionError: [({}, []), ({}, [])] is not an instance of <class 'dict'> : First argument is not a dictionary

----------------------------------------------------------------------
Ran 5 tests in 0.001s

FAILED (failures=3, errors=2)
